<mujoco>
        
        
        <body name="base_link" pos="0.8 0.8 1.0">
            <joint armature="0.0001" axis="1 0 0" damping="1e+11" name="robot0:slide0" pos="0 0 0" type="slide"></joint>
            <joint armature="0.0001" axis="0 1 0" damping="1e+11" name="robot0:slide1" pos="0 0 0" type="slide"></joint>
            <joint armature="0.0001" axis="0 0 1" damping="1e+11" name="robot0:slide2" pos="0 0 0" type="slide"></joint>
            <!-- <inertial diaginertia="1.2869 1.2236 0.9868" mass="70.1294" pos="-0.0036 0 0.0014" quat="0.7605 -0.0133 -0.0061 0.6491"></inertial> -->
            <!-- <geom mesh="robot0:base_link" name="robot0:base_link" material="robot0:base_mat" class="robot0:grey"></geom> -->
            <geom pos="0 0 -0.04695" type="mesh" mesh="hdt_mk3_m_0" />
            <geom type="mesh" mesh="hdt_mk3_m_ik" />
            <!-- hdt arm -->
            <body name="link1" pos="0 0 -0.04715">
                <inertial pos="-0.0445965 0 -0.0344774" quat="0.707095 -0.00408362 -0.00408362 0.707095" mass="1.6755" diaginertia="0.00496229 0.00428543 0.00214575" />
                <joint name="joint1" pos="0 0 0" axis="0 0 1" limited="true" range="-2.0944 2.0944" damping="0.7" />
                <geom type="mesh" mesh="hdt_mk3_m_1" />
                <geom pos="0 0 -0.08651" type="mesh" mesh="hdt_mk3_m_2a" />
                <body name="link2b" pos="0.0257 -0.042 -0.17351">
                    <inertial pos="-0.0200099 0.0326629 -0.172777" quat="0.904342 0.084665 0.0102102 0.418203" mass="3.14405" diaginertia="0.0342235 0.0338523 0.00251707" />
                    <joint name="joint2" pos="0 0 0" axis="1 0 0" limited="true" range="-3.1416 1.5708" damping="0.7" />
                    <geom type="mesh" mesh="hdt_mk3_m_2b" />
                    <geom pos="-0.02573 0.042 -0.107" type="mesh" mesh="hdt_mk3_m_3" />
                    <geom pos="-0.02573 0.042 -0.25011" type="mesh" mesh="hdt_mk3_m_4a" />
                    <body name="link4b" pos="-3e-05 0 -0.33711">
                        <inertial pos="0 -0.020181 0" quat="0.707107 0.707107 0 0" mass="0.698963" diaginertia="0.00094182 0.00088116 0.00032992" />
                        <joint name="joint4" pos="0 0 0" axis="1 0 0" limited="true" range="-1.5708 3.1416" damping="0.7" />
                        <geom type="mesh" mesh="hdt_mk3_m_4b" />
                        <body name="link5" pos="-0.02573 -0.1062 -0.042">
                            <inertial pos="0 -0.0723409 0" quat="0.5 0.5 -0.5 0.5" mass="1.50833" diaginertia="0.00408471 0.00391397 0.00119102" />
                            <joint name="joint5" pos="0 0 0" axis="0 -1 0" limited="true" range="-2.0944 2.0944" damping="0.7" />
                            <geom type="mesh" mesh="hdt_mk3_m_5" />
                            <geom pos="0 -0.08651 0" type="mesh" mesh="hdt_mk3_m_6a" />
                            <body name="link6b" pos="0.02393 -0.13751 0">
                                <inertial pos="0 -0.03855 0" quat="0.707107 0.707107 0 0" mass="0.99934" diaginertia="0.00190524 0.00190524 0.000474765" />
                                <joint name="joint6" pos="0 0 0" axis="1 0 0" limited="true" range="-1.5708 1.5708" damping="0.7" />
                                <geom type="mesh" mesh="hdt_mk3_m_6b" />
                                <body name="link7" pos="-0.02395 -0.082 -0.0279">
                                    <inertial pos="0.011538 -0.157503 0.00420786" quat="0.717957 0.693007 0.0519835 -0.0397044" mass="2.74632" diaginertia="0.0240513 0.0231018 0.00559065" />
                                    <joint name="joint7" pos="0 0 0" axis="0 0 1" limited="true" range="-1.5708 1.5708" damping="0.7" />
                                    <geom type="mesh" mesh="hdt_mk3_m_7" />
                                    <geom pos="-1e-05 -0.07 0.02793" type="mesh" mesh="hdt_mk3_m_palm" />
                                    <geom pos="-1e-05 -0.16629 0.02793" type="mesh" mesh="hdt_mk3_m_palm_pad" />
                                    <geom pos="-4.62e-05 -0.11079 -0.023044" type="mesh" mesh="hdt_mk3_m_camera_bracket" />
                                    <geom pos="0.0222334 -0.0943304 -0.0421013" quat="0.905128 -0.277926 -0.18527 0.263011" type="mesh" mesh="hdt_mk3_m_camera" />
                                    <!-- gripper finger thumb  -->
                                    <body name="thumb_base" pos="-4.62e-05 -0.128 0.045715">
                                        <!-- get the position from gripperpalm -->
                                        <site name="gripperpalm" pos="0 0 0" size="0.035 0.0055 0.035"/>
                                        <inertial pos="0 -0.0758237 -0.00179049" quat="0.633597 0.773663 0.000533945 8.60911e-05" mass="0.65318" diaginertia="0.00205483 0.00172361 0.000596046" />
                                        <joint name="thumb_base" pos="0 0 0" axis="0 -1 0" limited="true" range="-1.5708 1.5708" damping="0.7" />
                                        <geom type="mesh" mesh="hdt_mk3_m_thumb_base" />
                                        <geom type="mesh" mesh="hdt_mk3_m_thumb_pad" />
                                        <body name="thumb_prox" pos="0.00879 -0.021848 0.057028">
                                            <inertial pos="0 0.001 0.02063" quat="0.707033 -0.0102215 0.0102215 0.707033" mass="0.02523" diaginertia="5.37605e-06 4.718e-06 2.91895e-06" />
                                            <joint name="thumb_prox" pos="0 0 0" axis="1 0 0" limited="true" range="-0.7854 1.5708" damping="0.7" />
                                            <geom type="mesh" mesh="hdt_mk3_m_thumb_prox" />
                                            <body name="thumb_med" pos="0 -0.0005 0.0435">
                                                <inertial pos="0 -0.00353 0.01162" quat="0.705326 0.0501467 -0.0501467 0.705326" mass="0.0085" diaginertia="1.65272e-06 1.099e-06 9.6728e-07" />
                                                <joint name="thumb_med" pos="0 0 0" axis="1 0 0" limited="true" range="0 1.5708" damping="0.7" />
                                                <geom type="mesh" mesh="hdt_mk3_m_thumb_med" />
                                                <body name="thumb_dist" pos="0 -0.00045 0.0277">
                                                    <inertial pos="0 -0.00131 0.01323" quat="0.5 0.5 0.5 0.5" mass="0.0092" diaginertia="8.37e-07 6.95e-07 6.6e-07" />
                                                    <joint name="thumb_dist" pos="0 0 0" axis="1 0 0" limited="true" range="0 1.5708" damping="0.7" />
                                                    <geom type="mesh" mesh="hdt_mk3_m_thumb_dist" />
                                                </body>
                                            </body>
                                        </body>
                                    </body>
                                    <!-- gripper finger index  -->
                                    <body name="index_prox" pos="-4.62e-05 -0.235998 0.0637253">
                                        <inertial pos="-0.001 -0.02063 0" quat="0.707033 0.707033 -0.0102215 -0.0102215" mass="0.02523" diaginertia="5.37605e-06 4.718e-06 2.91895e-06" />
                                        <joint name="index_prox" pos="0 0 0" axis="0 0 1" limited="true" range="-0.7854 1.5708" damping="0.7" />
                                        <geom type="mesh" mesh="hdt_6dof_index_prox" />
                                        <body name="index_med" pos="-0.0005 -0.0435 0">
                                            <inertial pos="0.00353 -0.01162 0" quat="0.705326 0.705326 0.0501467 0.0501467" mass="0.0085" diaginertia="1.65272e-06 1.099e-06 9.6728e-07" />
                                            <joint name="index_med" pos="0 0 0" axis="0 0 1" limited="true" range="0 1.5708" damping="0.7" />
                                            <geom type="mesh" mesh="hdt_mk3_m_finger_med" />
                                            <body name="index_dist" pos="0.00045 -0.0277 0">
                                                <inertial pos="0.00131 -0.01323 0" mass="0.0092" diaginertia="8.37e-07 6.95e-07 6.6e-07" />
                                                <joint name="index_dist" pos="0 0 0" axis="0 0 1" limited="true" range="0 1.5708" damping="0.7" />
                                                <geom type="mesh" mesh="hdt_mk3_m_finger_dist" />
                                            </body>
                                        </body>
                                    </body>
                                    <!-- gripper finger ring -->
                                    <body name="ring_prox" pos="-4.62e-05 -0.235998 0.0097147">
                                        <inertial pos="-0.001 -0.02063 0" quat="0.707033 0.707033 -0.0102215 -0.0102215" mass="0.02523" diaginertia="5.37605e-06 4.718e-06 2.91895e-06" />
                                        <joint name="ring_prox" pos="0 0 0" axis="0 0 1" limited="true" range="-0.7854 1.5708" damping="0.7" />
                                        <geom type="mesh" mesh="hdt_6dof_ring_prox" />
                                        <body name="ring_med" pos="-0.0005 -0.0435 0">
                                            <inertial pos="0.00353 -0.01162 0" quat="0.705326 0.705326 0.0501467 0.0501467" mass="0.0085" diaginertia="1.65272e-06 1.099e-06 9.6728e-07" />
                                            <joint name="ring_med" pos="0 0 0" axis="0 0 1" limited="true" range="0 1.5708" damping="0.7" />
                                            <geom type="mesh" mesh="hdt_mk3_m_finger_med" />
                                            <body name="ring_dist" pos="0.00045 -0.0277 0">
                                                <inertial pos="0.00131 -0.01323 0" mass="0.0092" diaginertia="8.37e-07 6.95e-07 6.6e-07" />
                                                <joint name="ring_dist" pos="0 0 0" axis="0 0 1" limited="true" range="0 1.5708" damping="0.7" />
                                                <geom type="mesh" mesh="hdt_mk3_m_finger_dist" />
                                            </body>
                                        </body>
                                    </body>
                                </body>
                            </body>
                        </body>
                    </body>
                </body>
            </body>
        </body>
</mujoco>
